{
  "timestamp": "2025-07-28T10:07:20.294Z",
  "date": "20250728",
  "tests": {
    "jest": {
      "success": false,
      "error": "Command failed: npm test -- --json --coverage\nsh: 1: Syntax error: word unexpected\n",
      "rawOutput": "\n> nextjs@0.1.0 test\n> jest && node scripts/test-reporter.js || (node scripts/test-reporter.js && exit 1) --json --coverage\n\n"
    },
    "e2e": {
      "success": false,
      "error": "Command failed: npm run test:e2e -- --reporter=json",
      "rawOutput": "\n> nextjs@0.1.0 test:e2e\n> playwright test --reporter=json\n\n{\n  \"config\": {\n    \"configFile\": \"/home/futaro/project/StatVizForge_JikkenPy/app/frontend/playwright.config.ts\",\n    \"rootDir\": \"/home/futaro/project/StatVizForge_JikkenPy/app/frontend/e2e\",\n    \"forbidOnly\": false,\n    \"fullyParallel\": false,\n    \"globalSetup\": \"/home/futaro/project/StatVizForge_JikkenPy/app/frontend/test-utils/e2e-globalSetup.ts\",\n    \"globalTeardown\": \"/home/futaro/project/StatVizForge_JikkenPy/app/frontend/test-utils/e2e-globalTeardown.ts\",\n    \"globalTimeout\": 0,\n    \"grep\": {},\n    \"grepInvert\": null,\n    \"maxFailures\": 0,\n    \"metadata\": {},\n    \"preserveOutput\": \"always\",\n    \"reporter\": [\n      [\n        \"json\"\n      ]\n    ],\n    \"reportSlowTests\": {\n      \"max\": 5,\n      \"threshold\": 300000\n    },\n    \"quiet\": false,\n    \"projects\": [\n      {\n        \"outputDir\": \"/home/futaro/project/StatVizForge_JikkenPy/app/frontend/test-results\",\n        \"repeatEach\": 1,\n        \"retries\": 0,\n        \"metadata\": {},\n        \"id\": \"chromium\",\n        \"name\": \"chromium\",\n        \"testDir\": \"/home/futaro/project/StatVizForge_JikkenPy/app/frontend/e2e\",\n        \"testIgnore\": [\n          \"**/*\"\n        ],\n        \"testMatch\": [\n          \"**/*.@(spec|test).?(c|m)[jt]s?(x)\"\n        ],\n        \"timeout\": 30000\n      },\n      {\n        \"outputDir\": \"/home/futaro/project/StatVizForge_JikkenPy/app/frontend/test-results\",\n        \"repeatEach\": 1,\n        \"retries\": 0,\n        \"metadata\": {},\n        \"id\": \"firefox\",\n        \"name\": \"firefox\",\n        \"testDir\": \"/home/futaro/project/StatVizForge_JikkenPy/app/frontend/e2e\",\n        \"testIgnore\": [\n          \"**/*\"\n        ],\n        \"testMatch\": [\n          \"**/*.@(spec|test).?(c|m)[jt]s?(x)\"\n        ],\n        \"timeout\": 30000\n      },\n      {\n        \"outputDir\": \"/home/futaro/project/StatVizForge_JikkenPy/app/frontend/test-results\",\n        \"repeatEach\": 1,\n        \"retries\": 0,\n        \"metadata\": {},\n        \"id\": \"webkit\",\n        \"name\": \"webkit\",\n        \"testDir\": \"/home/futaro/project/StatVizForge_JikkenPy/app/frontend/e2e\",\n        \"testIgnore\": [\n          \"**/*\"\n        ],\n        \"testMatch\": [\n          \"**/*.@(spec|test).?(c|m)[jt]s?(x)\"\n        ],\n        \"timeout\": 30000\n      },\n      {\n        \"outputDir\": \"/home/futaro/project/StatVizForge_JikkenPy/app/frontend/test-results\",\n        \"repeatEach\": 1,\n        \"retries\": 0,\n        \"metadata\": {},\n        \"id\": \"Mobile Chrome\",\n        \"name\": \"Mobile Chrome\",\n        \"testDir\": \"/home/futaro/project/StatVizForge_JikkenPy/app/frontend/e2e\",\n        \"testIgnore\": [\n          \"**/*\"\n        ],\n        \"testMatch\": [\n          \"**/*.@(spec|test).?(c|m)[jt]s?(x)\"\n        ],\n        \"timeout\": 30000\n      },\n      {\n        \"outputDir\": \"/home/futaro/project/StatVizForge_JikkenPy/app/frontend/test-results\",\n        \"repeatEach\": 1,\n        \"retries\": 0,\n        \"metadata\": {},\n        \"id\": \"Mobile Safari\",\n        \"name\": \"Mobile Safari\",\n        \"testDir\": \"/home/futaro/project/StatVizForge_JikkenPy/app/frontend/e2e\",\n        \"testIgnore\": [\n          \"**/*\"\n        ],\n        \"testMatch\": [\n          \"**/*.@(spec|test).?(c|m)[jt]s?(x)\"\n        ],\n        \"timeout\": 30000\n      }\n    ],\n    \"shard\": null,\n    \"updateSnapshots\": \"missing\",\n    \"updateSourceMethod\": \"patch\",\n    \"version\": \"1.54.1\",\n    \"workers\": 1,\n    \"webServer\": null\n  },\n  \"suites\": [],\n  \"errors\": [\n    {\n      \"message\": \"Error: Process from config.webServer was not able to start. Exit code: 1\",\n      \"stack\": \"Error: Process from config.webServer was not able to start. Exit code: 1\"\n    }\n  ],\n  \"stats\": {\n    \"startTime\": \"2025-07-28T10:07:20.887Z\",\n    \"duration\": 993.712,\n    \"expected\": 0,\n    \"skipped\": 0,\n    \"unexpected\": 0,\n    \"flaky\": 0\n  }\n}\n"
    },
    "backend": {
      "success": false,
      "error": "Command failed: cd ../backend && source venv/bin/activate && python3 manage.py test --verbosity=2\nCreating test database for alias 'default' ('file:memorydb_default?mode=memory&cache=shared')...\ntest_concurrent_tag_operations (api.test_file_tags.FileTagsAPITestCase.test_concurrent_tag_operations)\n並行タグ操作テスト ... FAIL\ntest_file_tags_persistence (api.test_file_tags.FileTagsAPITestCase.test_file_tags_persistence)\nファイルタグ永続化テスト ... FAIL\ntest_get_all_file_tags_success (api.test_file_tags.FileTagsAPITestCase.test_get_all_file_tags_success)\n全ファイルタグ取得成功テスト ... FAIL\ntest_get_file_tags_success (api.test_file_tags.FileTagsAPITestCase.test_get_file_tags_success)\nファイルタグ取得成功テスト ... FAIL\ntest_project_not_found_error (api.test_file_tags.FileTagsAPITestCase.test_project_not_found_error)\n存在しないプロジェクトでのエラーテスト ... ok\ntest_save_file_tags_invalid_combination (api.test_file_tags.FileTagsAPITestCase.test_save_file_tags_invalid_combination)\n無効なタグ組み合わせテスト（項目データのみ） ... FAIL\ntest_save_file_tags_success (api.test_file_tags.FileTagsAPITestCase.test_save_file_tags_success)\nファイルタグ保存成功テスト ... FAIL\ntest_save_file_tags_validation_error (api.test_file_tags.FileTagsAPITestCase.test_save_file_tags_validation_error)\nファイルタグ保存バリデーションエラーテスト ... FAIL\ntest_search_files_by_multiple_tags (api.test_file_tags.FileTagsAPITestCase.test_search_files_by_multiple_tags)\n複数タグによる検索テスト ... ERROR\ntest_search_files_by_tags_success (api.test_file_tags.FileTagsAPITestCase.test_search_files_by_tags_success)\nタグによるファイル検索成功テスト ... ERROR\ntest_tag_api_error_handling (api.test_file_tags.FileTagsAPITestCase.test_tag_api_error_handling)\nタグAPIエラーハンドリングテスト ... FAIL\ntest_tag_api_response_format (api.test_file_tags.FileTagsAPITestCase.test_tag_api_response_format)\nタグAPIレスポンス形式テスト ... FAIL\ntest_tag_validation_rules (api.test_file_tags.FileTagsAPITestCase.test_tag_validation_rules)\nタグバリデーションルールテスト ... FAIL\ntest_get_jupyter_status_no_instances (api.test_jupyter_api.JupyterLabAPITestCase.test_get_jupyter_status_no_instances)\nJupyterLabインスタンスなしの状態確認テスト ... ERROR\ntest_get_jupyter_status_running (api.test_jupyter_api.JupyterLabAPITestCase.test_get_jupyter_status_running)\nJupyterLab状態確認（起動中）テスト ... ERROR\ntest_get_jupyter_status_specific_project (api.test_jupyter_api.JupyterLabAPITestCase.test_get_jupyter_status_specific_project)\n特定プロジェクトのJupyterLab状態確認テスト ... ERROR\ntest_jupyter_api_error_responses (api.test_jupyter_api.JupyterLabAPITestCase.test_jupyter_api_error_responses)\nJupyterLab API エラーレスポンス形式テスト ... ok\ntest_jupyter_api_performance (api.test_jupyter_api.JupyterLabAPITestCase.test_jupyter_api_performance)\nJupyterLab API パフォーマンステスト ... ERROR\ntest_jupyter_api_resource_management (api.test_jupyter_api.JupyterLabAPITestCase.test_jupyter_api_resource_management)\nJupyterLab API リソース管理テスト ... FAIL\ntest_jupyter_api_security (api.test_jupyter_api.JupyterLabAPITestCase.test_jupyter_api_security)\nJupyterLab API セキュリティテスト ... FAIL\ntest_jupyter_service_separation (api.test_jupyter_api.JupyterLabAPITestCase.test_jupyter_service_separation)\nJupyterLabサービス分離テスト ... ERROR\ntest_start_jupyter_lab_already_running (api.test_jupyter_api.JupyterLabAPITestCase.test_start_jupyter_lab_already_running)\n既に起動中のJupyterLabに対する処理テスト ... FAIL\ntest_start_jupyter_lab_missing_project_folder (api.test_jupyter_api.JupyterLabAPITestCase.test_start_jupyter_lab_missing_project_folder)\nプロジェクトフォルダ未指定エラーテスト ... ok\ntest_start_jupyter_lab_project_not_found (api.test_jupyter_api.JupyterLabAPITestCase.test_start_jupyter_lab_project_not_found)\n存在しないプロジェクトでのエラーテスト ... ok\ntest_start_jupyter_lab_startup_failure (api.test_jupyter_api.JupyterLabAPITestCase.test_start_jupyter_lab_startup_failure)\nJupyterLab起動失敗テスト ... FAIL\ntest_start_jupyter_lab_success (api.test_jupyter_api.JupyterLabAPITestCase.test_start_jupyter_lab_success)\nJupyterLab起動成功テスト ... FAIL\ntest_stop_jupyter_lab_not_running (api.test_jupyter_api.JupyterLabAPITestCase.test_stop_jupyter_lab_not_running)\n起動していないJupyterLabの停止テスト ... ERROR\ntest_stop_jupyter_lab_success (api.test_jupyter_api.JupyterLabAPITestCase.test_stop_jupyter_lab_success)\nJupyterLab停止成功テスト ... ERROR\ntest_full_workflow_integration (api.tests.APIIntegrationTestCase.test_full_workflow_integration)\n完全ワークフロー統合テスト：プロジェクト作成→ファイル操作→コメント→検索 ... ERROR\ntest_add_file_comment (api.tests.FileCommentsTestCase.test_add_file_comment)\nファイルコメント追加テスト ... FAIL\ntest_add_file_comment (api.tests.FileCommentsTestCase.test_add_file_comment)\nファイルコメント追加テスト ... ERROR\ntest_comment_api_validation (api.tests.FileCommentsTestCase.test_comment_api_validation)\nコメントAPI バリデーションテスト ... FAIL\ntest_comment_api_validation (api.tests.FileCommentsTestCase.test_comment_api_validation)\nコメントAPI バリデーションテスト ... ERROR\ntest_delete_file_comment (api.tests.FileCommentsTestCase.test_delete_file_comment)\nファイルコメント削除テスト ... FAIL\ntest_delete_file_comment (api.tests.FileCommentsTestCase.test_delete_file_comment)\nファイルコメント削除テスト ... ERROR\ntest_get_file_comments (api.tests.FileCommentsTestCase.test_get_file_comments)\nファイルコメント取得テスト ... FAIL\ntest_get_file_comments (api.tests.FileCommentsTestCase.test_get_file_comments)\nファイルコメント取得テスト ... ERROR\ntest_update_file_comment (api.tests.FileCommentsTestCase.test_update_file_comment)\nファイルコメント更新テスト ... FAIL\ntest_update_file_comment (api.tests.FileCommentsTestCase.test_update_file_comment)\nファイルコメント更新テスト ... ERROR\ntest_directory_creation (api.tests.FileManagementTestCase.test_directory_creation)\nディレクトリ作成テスト ... FAIL\ntest_directory_creation (api.tests.FileManagementTestCase.test_directory_creation)\nディレクトリ作成テスト ... ERROR\ntest_directory_tree_retrieval (api.tests.FileManagementTestCase.test_directory_tree_retrieval)\nディレクトリツリー取得テスト ... FAIL\ntest_directory_tree_retrieval (api.tests.FileManagementTestCase.test_directory_tree_retrieval)\nディレクトリツリー取得テスト ... ERROR\ntest_file_api_error_handling (api.tests.FileManagementTestCase.test_file_api_error_handling)\nファイルAPI エラーハンドリングテスト ... FAIL\ntest_file_api_error_handling (api.tests.FileManagementTestCase.test_file_api_error_handling)\nファイルAPI エラーハンドリングテスト ... ERROR\ntest_file_deletion (api.tests.FileManagementTestCase.test_file_deletion)\nファイル削除テスト ... FAIL\ntest_file_deletion (api.tests.FileManagementTestCase.test_file_deletion)\nファイル削除テスト ... ERROR\ntest_file_move (api.tests.FileManagementTestCase.test_file_move)\nファイル移動テスト ... FAIL\ntest_file_move (api.tests.FileManagementTestCase.test_file_move)\nファイル移動テスト ... ERROR\ntest_file_search (api.tests.FileManagementTestCase.test_file_search)\nファイル検索テスト ... FAIL\ntest_file_search (api.tests.FileManagementTestCase.test_file_search)\nファイル検索テスト ... ERROR\ntest_multiple_file_upload (api.tests.FileManagementTestCase.test_multiple_file_upload)\n複数ファイルアップロードテスト ... FAIL\ntest_multiple_file_upload (api.tests.FileManagementTestCase.test_multiple_file_upload)\n複数ファイルアップロードテスト ... ERROR\ntest_single_file_upload (api.tests.FileManagementTestCase.test_single_file_upload)\n単一ファイルアップロードテスト ... FAIL\ntest_single_file_upload (api.tests.FileManagementTestCase.test_single_file_upload)\n単一ファイルアップロードテスト ... ERROR\ntest_api_response_time (api.tests.ProjectAPIPerformanceTestCase.test_api_response_time)\nAPI応答時間テスト ... ok\ntest_プロジェクトライフサイクル_エラー混在 (api.tests.ProjectIntegrationTestCase.test_プロジェクトライフサイクル_エラー混在)\n正常操作とエラー操作が混在するライフサイクル ... ERROR\ntest_同時削除復元操作 (api.tests.ProjectIntegrationTestCase.test_同時削除復元操作)\n複数プロジェクトの同時削除・復元操作 ... ERROR\ntest_complete_project_lifecycle (api.tests.ProjectLifecycleTestCase.test_complete_project_lifecycle)\nプロジェクト完全ライフサイクルテスト: 作成→更新→削除→復元 ... ERROR\ntest_error_handling_scenarios (api.tests.ProjectLifecycleTestCase.test_error_handling_scenarios)\nエラーハンドリングシナリオテスト ... ERROR\ntest_language_parameter_handling (api.tests.ProjectLifecycleTestCase.test_language_parameter_handling)\n言語パラメータ処理テスト（エラーメッセージのみ） ... ERROR\ntest_multiple_projects_interaction (api.tests.ProjectLifecycleTestCase.test_multiple_projects_interaction)\n複数プロジェクトの相互作用テスト ... ERROR\ntest_タグ配列バリデーション_0__ (api.tests.ProjectValidationTestCase.test_タグ配列バリデーション_0__)\n様々なタグ配列のバリデーション [with test_name='空のタグ配列', tags=[]] ... ERROR\ntest_タグ配列バリデーション_1__ (api.tests.ProjectValidationTestCase.test_タグ配列バリデーション_1__)\n様々なタグ配列のバリデーション [with test_name='単一タグ', tags=['tag1']] ... ERROR\ntest_タグ配列バリデーション_2__ (api.tests.ProjectValidationTestCase.test_タグ配列バリデーション_2__)\n様々なタグ配列のバリデーション [with test_name='複数タグ', tags=['tag1', 'tag2', 'tag3']] ... ERROR\ntest_タグ配列バリデーション_3__ (api.tests.ProjectValidationTestCase.test_タグ配列バリデーション_3__)\n様々なタグ配列のバリデーション [with test_name='日本語タグ', tags=['日本語', 'テスト', 'サンプル']] ... ERROR\ntest_タグ配列バリデーション_4__ (api.tests.ProjectValidationTestCase.test_タグ配列バリデーション_4__)\n様々なタグ配列のバリデーション [with test_name='英数字タグ', tags=['test', 'sample', 'demo123']] ... ERROR\ntest_プロジェクト名バリデーション (api.tests.ProjectValidationTestCase.test_プロジェクト名バリデーション)\nプロジェクト名の長さと文字種バリデーション ... ERROR\ntest_重複フォルダ名チェック (api.tests.ProjectValidationTestCase.test_重複フォルダ名チェック)\nフォルダ名の重複チェック ... ERROR\n\n======================================================================\nERROR: test_search_files_by_multiple_tags (api.test_file_tags.FileTagsAPITestCase.test_search_files_by_multiple_tags)\n複数タグによる検索テスト\n----------------------------------------------------------------------\nTraceback (most recent call last):\n  File \"/home/futaro/project/StatVizForge_JikkenPy/app/backend/api/test_file_tags.py\", line 161, in test_search_files_by_multiple_tags\n    with patch('api.views.FileViewSet.search_by_tags') as mock_search:\n  File \"/usr/lib/python3.12/unittest/mock.py\", line 1458, in __enter__\n    original, local = self.get_original()\n                      ^^^^^^^^^^^^^^^^^^^\n  File \"/usr/lib/python3.12/unittest/mock.py\", line 1431, in get_original\n    raise AttributeError(\nAttributeError: <class 'api.views.FileViewSet'> does not have the attribute 'search_by_tags'\n\n======================================================================\nERROR: test_search_files_by_tags_success (api.test_file_tags.FileTagsAPITestCase.test_search_files_by_tags_success)\nタグによるファイル検索成功テスト\n----------------------------------------------------------------------\nTraceback (most recent call last):\n  File \"/home/futaro/project/StatVizForge_JikkenPy/app/backend/api/test_file_tags.py\", line 135, in test_search_files_by_tags_success\n    with patch('api.views.FileViewSet.search_by_tags') as mock_search:\n  File \"/usr/lib/python3.12/unittest/mock.py\", line 1458, in __enter__\n    original, local = self.get_original()\n                      ^^^^^^^^^^^^^^^^^^^\n  File \"/usr/lib/python3.12/unittest/mock.py\", line 1431, in get_original\n    raise AttributeError(\nAttributeError: <class 'api.views.FileViewSet'> does not have the attribute 'search_by_tags'\n\n======================================================================\nERROR: test_get_jupyter_status_no_instances (api.test_jupyter_api.JupyterLabAPITestCase.test_get_jupyter_status_no_instances)\nJupyterLabインスタンスなしの状態確認テスト\n----------------------------------------------------------------------\nTraceback (most recent call last):\n  File \"/usr/lib/python3.12/unittest/mock.py\", line 1387, in patched\n    with self.decoration_helper(patched,\n  File \"/usr/lib/python3.12/contextlib.py\", line 137, in __enter__\n    return next(self.gen)\n           ^^^^^^^^^^^^^^\n  File \"/usr/lib/python3.12/unittest/mock.py\", line 1369, in decoration_helper\n    arg = exit_stack.enter_context(patching)\n          ^^^^^^^^^^^^^^^^^^^^^^^^^^^^^^^^^^\n  File \"/usr/lib/python3.12/contextlib.py\", line 526, in enter_context\n    result = _enter(cm)\n             ^^^^^^^^^^\n  File \"/usr/lib/python3.12/unittest/mock.py\", line 1458, in __enter__\n    original, local = self.get_original()\n                      ^^^^^^^^^^^^^^^^^^^\n  File \"/usr/lib/python3.12/unittest/mock.py\", line 1431, in get_original\n    raise AttributeError(\nAttributeError: <module 'api.views' from '/home/futaro/project/StatVizForge_JikkenPy/app/backend/api/views.py'> does not have the attribute 'get_jupyter_status'\n\n======================================================================\nERROR: test_get_jupyter_status_running (api.test_jupyter_api.JupyterLabAPITestCase.test_get_jupyter_status_running)\nJupyterLab状態確認（起動中）テスト\n----------------------------------------------------------------------\nTraceback (most recent call last):\n  File \"/usr/lib/python3.12/unittest/mock.py\", line 1387, in patched\n    with self.decoration_helper(patched,\n  File \"/usr/lib/python3.12/contextlib.py\", line 137, in __enter__\n    return next(self.gen)\n           ^^^^^^^^^^^^^^\n  File \"/usr/lib/python3.12/unittest/mock.py\", line 1369, in decoration_helper\n    arg = exit_stack.enter_context(patching)\n          ^^^^^^^^^^^^^^^^^^^^^^^^^^^^^^^^^^\n  File \"/usr/lib/python3.12/contextlib.py\", line 526, in enter_context\n    result = _enter(cm)\n             ^^^^^^^^^^\n  File \"/usr/lib/python3.12/unittest/mock.py\", line 1458, in __enter__\n    original, local = self.get_original()\n                      ^^^^^^^^^^^^^^^^^^^\n  File \"/usr/lib/python3.12/unittest/mock.py\", line 1431, in get_original\n    raise AttributeError(\nAttributeError: <module 'api.views' from '/home/futaro/project/StatVizForge_JikkenPy/app/backend/api/views.py'> does not have the attribute 'get_jupyter_status'\n\n======================================================================\nERROR: test_get_jupyter_status_specific_project (api.test_jupyter_api.JupyterLabAPITestCase.test_get_jupyter_status_specific_project)\n特定プロジェクトのJupyterLab状態確認テスト\n----------------------------------------------------------------------\nTraceback (most recent call last):\n  File \"/usr/lib/python3.12/unittest/mock.py\", line 1387, in patched\n    with self.decoration_helper(patched,\n  File \"/usr/lib/python3.12/contextlib.py\", line 137, in __enter__\n    return next(self.gen)\n           ^^^^^^^^^^^^^^\n  File \"/usr/lib/python3.12/unittest/mock.py\", line 1369, in decoration_helper\n    arg = exit_stack.enter_context(patching)\n          ^^^^^^^^^^^^^^^^^^^^^^^^^^^^^^^^^^\n  File \"/usr/lib/python3.12/contextlib.py\", line 526, in enter_context\n    result = _enter(cm)\n             ^^^^^^^^^^\n  File \"/usr/lib/python3.12/unittest/mock.py\", line 1458, in __enter__\n    original, local = self.get_original()\n                      ^^^^^^^^^^^^^^^^^^^\n  File \"/usr/lib/python3.12/unittest/mock.py\", line 1431, in get_original\n    raise AttributeError(\nAttributeError: <module 'api.views' from '/home/futaro/project/StatVizForge_JikkenPy/app/backend/api/views.py'> does not have the attribute 'get_jupyter_status'\n\n======================================================================\nERROR: test_jupyter_api_performance (api.test_jupyter_api.JupyterLabAPITestCase.test_jupyter_api_performance)\nJupyterLab API パフォーマンステスト\n----------------------------------------------------------------------\nTraceback (most recent call last):\n  File \"/usr/lib/python3.12/unittest/mock.py\", line 1387, in patched\n    with self.decoration_helper(patched,\n  File \"/usr/lib/python3.12/contextlib.py\", line 137, in __enter__\n    return next(self.gen)\n           ^^^^^^^^^^^^^^\n  File \"/usr/lib/python3.12/unittest/mock.py\", line 1369, in decoration_helper\n    arg = exit_stack.enter_context(patching)\n          ^^^^^^^^^^^^^^^^^^^^^^^^^^^^^^^^^^\n  File \"/usr/lib/python3.12/contextlib.py\", line 526, in enter_context\n    result = _enter(cm)\n             ^^^^^^^^^^\n  File \"/usr/lib/python3.12/unittest/mock.py\", line 1458, in __enter__\n    original, local = self.get_original()\n                      ^^^^^^^^^^^^^^^^^^^\n  File \"/usr/lib/python3.12/unittest/mock.py\", line 1431, in get_original\n    raise AttributeError(\nAttributeError: <module 'api.views' from '/home/futaro/project/StatVizForge_JikkenPy/app/backend/api/views.py'> does not have the attribute 'get_jupyter_status'\n\n======================================================================\nERROR: test_jupyter_service_separation (api.test_jupyter_api.JupyterLabAPITestCase.test_jupyter_service_separation)\nJupyterLabサービス分離テスト\n----------------------------------------------------------------------\nTraceback (most recent call last):\n  File \"/usr/lib/python3.12/unittest/mock.py\", line 1387, in patched\n    with self.decoration_helper(patched,\n  File \"/usr/lib/python3.12/contextlib.py\", line 137, in __enter__\n    return next(self.gen)\n           ^^^^^^^^^^^^^^\n  File \"/usr/lib/python3.12/unittest/mock.py\", line 1369, in decoration_helper\n    arg = exit_stack.enter_context(patching)\n          ^^^^^^^^^^^^^^^^^^^^^^^^^^^^^^^^^^\n  File \"/usr/lib/python3.12/contextlib.py\", line 526, in enter_context\n    result = _enter(cm)\n             ^^^^^^^^^^\n  File \"/usr/lib/python3.12/unittest/mock.py\", line 1458, in __enter__\n    original, local = self.get_original()\n                      ^^^^^^^^^^^^^^^^^^^\n  File \"/usr/lib/python3.12/unittest/mock.py\", line 1431, in get_original\n    raise AttributeError(\nAttributeError: <module 'api.views' from '/home/futaro/project/StatVizForge_JikkenPy/app/backend/api/views.py'> does not have the attribute 'jupyter_service'\n\n======================================================================\nERROR: test_stop_jupyter_lab_not_running (api.test_jupyter_api.JupyterLabAPITestCase.test_stop_jupyter_lab_not_running)\n起動していないJupyterLabの停止テスト\n----------------------------------------------------------------------\nTraceback (most recent call last):\n  File \"/usr/lib/python3.12/unittest/mock.py\", line 1387, in patched\n    with self.decoration_helper(patched,\n  File \"/usr/lib/python3.12/contextlib.py\", line 137, in __enter__\n    return next(self.gen)\n           ^^^^^^^^^^^^^^\n  File \"/usr/lib/python3.12/unittest/mock.py\", line 1369, in decoration_helper\n    arg = exit_stack.enter_context(patching)\n          ^^^^^^^^^^^^^^^^^^^^^^^^^^^^^^^^^^\n  File \"/usr/lib/python3.12/contextlib.py\", line 526, in enter_context\n    result = _enter(cm)\n             ^^^^^^^^^^\n  File \"/usr/lib/python3.12/unittest/mock.py\", line 1458, in __enter__\n    original, local = self.get_original()\n                      ^^^^^^^^^^^^^^^^^^^\n  File \"/usr/lib/python3.12/unittest/mock.py\", line 1431, in get_original\n    raise AttributeError(\nAttributeError: <module 'api.views' from '/home/futaro/project/StatVizForge_JikkenPy/app/backend/api/views.py'> does not have the attribute 'stop_jupyter_lab'\n\n======================================================================\nERROR: test_stop_jupyter_lab_success (api.test_jupyter_api.JupyterLabAPITestCase.test_stop_jupyter_lab_success)\nJupyterLab停止成功テスト\n----------------------------------------------------------------------\nTraceback (most recent call last):\n  File \"/usr/lib/python3.12/unittest/mock.py\", line 1387, in patched\n    with self.decoration_helper(patched,\n  File \"/usr/lib/python3.12/contextlib.py\", line 137, in __enter__\n    return next(self.gen)\n           ^^^^^^^^^^^^^^\n  File \"/usr/lib/python3.12/unittest/mock.py\", line 1369, in decoration_helper\n    arg = exit_stack.enter_context(patching)\n          ^^^^^^^^^^^^^^^^^^^^^^^^^^^^^^^^^^\n  File \"/usr/lib/python3.12/contextlib.py\", line 526, in enter_context\n    result = _enter(cm)\n             ^^^^^^^^^^\n  File \"/usr/lib/python3.12/unittest/mock.py\", line 1458, in __enter__\n    original, local = self.get_original()\n                      ^^^^^^^^^^^^^^^^^^^\n  File \"/usr/lib/python3.12/unittest/mock.py\", line 1431, in get_original\n    raise AttributeError(\nAttributeError: <module 'api.views' from '/home/futaro/project/StatVizForge_JikkenPy/app/backend/api/views.py'> does not have the attribute 'stop_jupyter_lab'\n\n======================================================================\nERROR: test_full_workflow_integration (api.tests.APIIntegrationTestCase.test_full_workflow_integration)\n完全ワークフロー統合テスト：プロジェクト作成→ファイル操作→コメント→検索\n----------------------------------------------------------------------\nTraceback (most recent call last):\n  File \"/home/futaro/project/StatVizForge_JikkenPy/app/backend/api/test_base.py\", line 47, in setUp\n    self.mock_load_trash = load_trash_patcher.start()\n                           ^^^^^^^^^^^^^^^^^^^^^^^^^^\n  File \"/usr/lib/python3.12/unittest/mock.py\", line 1606, in start\n    result = self.__enter__()\n             ^^^^^^^^^^^^^^^^\n  File \"/usr/lib/python3.12/unittest/mock.py\", line 1458, in __enter__\n    original, local = self.get_original()\n                      ^^^^^^^^^^^^^^^^^^^\n  File \"/usr/lib/python3.12/unittest/mock.py\", line 1431, in get_original\n    raise AttributeError(\nAttributeError: <module 'api.utils' from '/home/futaro/project/StatVizForge_JikkenPy/app/backend/api/utils.py'> does not have the attribute 'load_trash_registry'\n\n======================================================================\nERROR: test_add_file_comment (api.tests.FileCommentsTestCase.test_add_file_comment)\nファイルコメント追加テスト\n----------------------------------------------------------------------\nTraceback (most recent call last):\n  File \"/home/futaro/project/StatVizForge_JikkenPy/app/backend/api/test_base.py\", line 96, in tearDown\n    for patcher in self.patchers:\n                   ^^^^^^^^^^^^^\nAttributeError: 'FileCommentsTestCase' object has no attribute 'patchers'\n\n======================================================================\nERROR: test_comment_api_validation (api.tests.FileCommentsTestCase.test_comment_api_validation)\nコメントAPI バリデーションテスト\n----------------------------------------------------------------------\nTraceback (most recent call last):\n  File \"/home/futaro/project/StatVizForge_JikkenPy/app/backend/api/test_base.py\", line 96, in tearDown\n    for patcher in self.patchers:\n                   ^^^^^^^^^^^^^\nAttributeError: 'FileCommentsTestCase' object has no attribute 'patchers'\n\n======================================================================\nERROR: test_delete_file_comment (api.tests.FileCommentsTestCase.test_delete_file_comment)\nファイルコメント削除テスト\n----------------------------------------------------------------------\nTraceback (most recent call last):\n  File \"/home/futaro/project/StatVizForge_JikkenPy/app/backend/api/test_base.py\", line 96, in tearDown\n    for patcher in self.patchers:\n                   ^^^^^^^^^^^^^\nAttributeError: 'FileCommentsTestCase' object has no attribute 'patchers'\n\n======================================================================\nERROR: test_get_file_comments (api.tests.FileCommentsTestCase.test_get_file_comments)\nファイルコメント取得テスト\n----------------------------------------------------------------------\nTraceback (most recent call last):\n  File \"/home/futaro/project/StatVizForge_JikkenPy/app/backend/api/test_base.py\", line 96, in tearDown\n    for patcher in self.patchers:\n                   ^^^^^^^^^^^^^\nAttributeError: 'FileCommentsTestCase' object has no attribute 'patchers'\n\n======================================================================\nERROR: test_update_file_comment (api.tests.FileCommentsTestCase.test_update_file_comment)\nファイルコメント更新テスト\n----------------------------------------------------------------------\nTraceback (most recent call last):\n  File \"/home/futaro/project/StatVizForge_JikkenPy/app/backend/api/test_base.py\", line 96, in tearDown\n    for patcher in self.patchers:\n                   ^^^^^^^^^^^^^\nAttributeError: 'FileCommentsTestCase' object has no attribute 'patchers'\n\n======================================================================\nERROR: test_directory_creation (api.tests.FileManagementTestCase.test_directory_creation)\nディレクトリ作成テスト\n----------------------------------------------------------------------\nTraceback (most recent call last):\n  File \"/home/futaro/project/StatVizForge_JikkenPy/app/backend/api/test_base.py\", line 96, in tearDown\n    for patcher in self.patchers:\n                   ^^^^^^^^^^^^^\nAttributeError: 'FileManagementTestCase' object has no attribute 'patchers'\n\n======================================================================\nERROR: test_directory_tree_retrieval (api.tests.FileManagementTestCase.test_directory_tree_retrieval)\nディレクトリツリー取得テスト\n----------------------------------------------------------------------\nTraceback (most recent call last):\n  File \"/home/futaro/project/StatVizForge_JikkenPy/app/backend/api/test_base.py\", line 96, in tearDown\n    for patcher in self.patchers:\n                   ^^^^^^^^^^^^^\nAttributeError: 'FileManagementTestCase' object has no attribute 'patchers'\n\n======================================================================\nERROR: test_file_api_error_handling (api.tests.FileManagementTestCase.test_file_api_error_handling)\nファイルAPI エラーハンドリングテスト\n----------------------------------------------------------------------\nTraceback (most recent call last):\n  File \"/home/futaro/project/StatVizForge_JikkenPy/app/backend/api/test_base.py\", line 96, in tearDown\n    for patcher in self.patchers:\n                   ^^^^^^^^^^^^^\nAttributeError: 'FileManagementTestCase' object has no attribute 'patchers'\n\n======================================================================\nERROR: test_file_deletion (api.tests.FileManagementTestCase.test_file_deletion)\nファイル削除テスト\n----------------------------------------------------------------------\nTraceback (most recent call last):\n  File \"/home/futaro/project/StatVizForge_JikkenPy/app/backend/api/test_base.py\", line 96, in tearDown\n    for patcher in self.patchers:\n                   ^^^^^^^^^^^^^\nAttributeError: 'FileManagementTestCase' object has no attribute 'patchers'\n\n======================================================================\nERROR: test_file_move (api.tests.FileManagementTestCase.test_file_move)\nファイル移動テスト\n----------------------------------------------------------------------\nTraceback (most recent call last):\n  File \"/home/futaro/project/StatVizForge_JikkenPy/app/backend/api/test_base.py\", line 96, in tearDown\n    for patcher in self.patchers:\n                   ^^^^^^^^^^^^^\nAttributeError: 'FileManagementTestCase' object has no attribute 'patchers'\n\n======================================================================\nERROR: test_file_search (api.tests.FileManagementTestCase.test_file_search)\nファイル検索テスト\n----------------------------------------------------------------------\nTraceback (most recent call last):\n  File \"/home/futaro/project/StatVizForge_JikkenPy/app/backend/api/test_base.py\", line 96, in tearDown\n    for patcher in self.patchers:\n                   ^^^^^^^^^^^^^\nAttributeError: 'FileManagementTestCase' object has no attribute 'patchers'\n\n======================================================================\nERROR: test_multiple_file_upload (api.tests.FileManagementTestCase.test_multiple_file_upload)\n複数ファイルアップロードテスト\n----------------------------------------------------------------------\nTraceback (most recent call last):\n  File \"/home/futaro/project/StatVizForge_JikkenPy/app/backend/api/test_base.py\", line 96, in tearDown\n    for patcher in self.patchers:\n                   ^^^^^^^^^^^^^\nAttributeError: 'FileManagementTestCase' object has no attribute 'patchers'\n\n======================================================================\nERROR: test_single_file_upload (api.tests.FileManagementTestCase.test_single_file_upload)\n単一ファイルアップロードテスト\n----------------------------------------------------------------------\nTraceback (most recent call last):\n  File \"/home/futaro/project/StatVizForge_JikkenPy/app/backend/api/test_base.py\", line 96, in tearDown\n    for patcher in self.patchers:\n                   ^^^^^^^^^^^^^\nAttributeError: 'FileManagementTestCase' object has no attribute 'patchers'\n\n======================================================================\nERROR: test_プロジェクトライフサイクル_エラー混在 (api.tests.ProjectIntegrationTestCase.test_プロジェクトライフサイクル_エラー混在)\n正常操作とエラー操作が混在するライフサイクル\n----------------------------------------------------------------------\nTraceback (most recent call last):\n  File \"/home/futaro/project/StatVizForge_JikkenPy/app/backend/api/test_base.py\", line 47, in setUp\n    self.mock_load_trash = load_trash_patcher.start()\n                           ^^^^^^^^^^^^^^^^^^^^^^^^^^\n  File \"/usr/lib/python3.12/unittest/mock.py\", line 1606, in start\n    result = self.__enter__()\n             ^^^^^^^^^^^^^^^^\n  File \"/usr/lib/python3.12/unittest/mock.py\", line 1458, in __enter__\n    original, local = self.get_original()\n                      ^^^^^^^^^^^^^^^^^^^\n  File \"/usr/lib/python3.12/unittest/mock.py\", line 1431, in get_original\n    raise AttributeError(\nAttributeError: <module 'api.utils' from '/home/futaro/project/StatVizForge_JikkenPy/app/backend/api/utils.py'> does not have the attribute 'load_trash_registry'\n\n======================================================================\nERROR: test_同時削除復元操作 (api.tests.ProjectIntegrationTestCase.test_同時削除復元操作)\n複数プロジェクトの同時削除・復元操作\n----------------------------------------------------------------------\nTraceback (most recent call last):\n  File \"/home/futaro/project/StatVizForge_JikkenPy/app/backend/api/test_base.py\", line 47, in setUp\n    self.mock_load_trash = load_trash_patcher.start()\n                           ^^^^^^^^^^^^^^^^^^^^^^^^^^\n  File \"/usr/lib/python3.12/unittest/mock.py\", line 1606, in start\n    result = self.__enter__()\n             ^^^^^^^^^^^^^^^^\n  File \"/usr/lib/python3.12/unittest/mock.py\", line 1458, in __enter__\n    original, local = self.get_original()\n                      ^^^^^^^^^^^^^^^^^^^\n  File \"/usr/lib/python3.12/unittest/mock.py\", line 1431, in get_original\n    raise AttributeError(\nAttributeError: <module 'api.utils' from '/home/futaro/project/StatVizForge_JikkenPy/app/backend/api/utils.py'> does not have the attribute 'load_trash_registry'\n\n======================================================================\nERROR: test_complete_project_lifecycle (api.tests.ProjectLifecycleTestCase.test_complete_project_lifecycle)\nプロジェクト完全ライフサイクルテスト: 作成→更新→削除→復元\n----------------------------------------------------------------------\nTraceback (most recent call last):\n  File \"/home/futaro/project/StatVizForge_JikkenPy/app/backend/api/tests.py\", line 22, in setUp\n    super().setUp()\n  File \"/home/futaro/project/StatVizForge_JikkenPy/app/backend/api/test_base.py\", line 47, in setUp\n    self.mock_load_trash = load_trash_patcher.start()\n                           ^^^^^^^^^^^^^^^^^^^^^^^^^^\n  File \"/usr/lib/python3.12/unittest/mock.py\", line 1606, in start\n    result = self.__enter__()\n             ^^^^^^^^^^^^^^^^\n  File \"/usr/lib/python3.12/unittest/mock.py\", line 1458, in __enter__\n    original, local = self.get_original()\n                      ^^^^^^^^^^^^^^^^^^^\n  File \"/usr/lib/python3.12/unittest/mock.py\", line 1431, in get_original\n    raise AttributeError(\nAttributeError: <module 'api.utils' from '/home/futaro/project/StatVizForge_JikkenPy/app/backend/api/utils.py'> does not have the attribute 'load_trash_registry'\n\n======================================================================\nERROR: test_error_handling_scenarios (api.tests.ProjectLifecycleTestCase.test_error_handling_scenarios)\nエラーハンドリングシナリオテスト\n----------------------------------------------------------------------\nTraceback (most recent call last):\n  File \"/home/futaro/project/StatVizForge_JikkenPy/app/backend/api/tests.py\", line 22, in setUp\n    super().setUp()\n  File \"/home/futaro/project/StatVizForge_JikkenPy/app/backend/api/test_base.py\", line 47, in setUp\n    self.mock_load_trash = load_trash_patcher.start()\n                           ^^^^^^^^^^^^^^^^^^^^^^^^^^\n  File \"/usr/lib/python3.12/unittest/mock.py\", line 1606, in start\n    result = self.__enter__()\n             ^^^^^^^^^^^^^^^^\n  File \"/usr/lib/python3.12/unittest/mock.py\", line 1458, in __enter__\n    original, local = self.get_original()\n                      ^^^^^^^^^^^^^^^^^^^\n  File \"/usr/lib/python3.12/unittest/mock.py\", line 1431, in get_original\n    raise AttributeError(\nAttributeError: <module 'api.utils' from '/home/futaro/project/StatVizForge_JikkenPy/app/backend/api/utils.py'> does not have the attribute 'load_trash_registry'\n\n======================================================================\nERROR: test_language_parameter_handling (api.tests.ProjectLifecycleTestCase.test_language_parameter_handling)\n言語パラメータ処理テスト（エラーメッセージのみ）\n----------------------------------------------------------------------\nTraceback (most recent call last):\n  File \"/home/futaro/project/StatVizForge_JikkenPy/app/backend/api/tests.py\", line 22, in setUp\n    super().setUp()\n  File \"/home/futaro/project/StatVizForge_JikkenPy/app/backend/api/test_base.py\", line 47, in setUp\n    self.mock_load_trash = load_trash_patcher.start()\n                           ^^^^^^^^^^^^^^^^^^^^^^^^^^\n  File \"/usr/lib/python3.12/unittest/mock.py\", line 1606, in start\n    result = self.__enter__()\n             ^^^^^^^^^^^^^^^^\n  File \"/usr/lib/python3.12/unittest/mock.py\", line 1458, in __enter__\n    original, local = self.get_original()\n                      ^^^^^^^^^^^^^^^^^^^\n  File \"/usr/lib/python3.12/unittest/mock.py\", line 1431, in get_original\n    raise AttributeError(\nAttributeError: <module 'api.utils' from '/home/futaro/project/StatVizForge_JikkenPy/app/backend/api/utils.py'> does not have the attribute 'load_trash_registry'\n\n======================================================================\nERROR: test_multiple_projects_interaction (api.tests.ProjectLifecycleTestCase.test_multiple_projects_interaction)\n複数プロジェクトの相互作用テスト\n----------------------------------------------------------------------\nTraceback (most recent call last):\n  File \"/home/futaro/project/StatVizForge_JikkenPy/app/backend/api/tests.py\", line 22, in setUp\n    super().setUp()\n  File \"/home/futaro/project/StatVizForge_JikkenPy/app/backend/api/test_base.py\", line 47, in setUp\n    self.mock_load_trash = load_trash_patcher.start()\n                           ^^^^^^^^^^^^^^^^^^^^^^^^^^\n  File \"/usr/lib/python3.12/unittest/mock.py\", line 1606, in start\n    result = self.__enter__()\n             ^^^^^^^^^^^^^^^^\n  File \"/usr/lib/python3.12/unittest/mock.py\", line 1458, in __enter__\n    original, local = self.get_original()\n                      ^^^^^^^^^^^^^^^^^^^\n  File \"/usr/lib/python3.12/unittest/mock.py\", line 1431, in get_original\n    raise AttributeError(\nAttributeError: <module 'api.utils' from '/home/futaro/project/StatVizForge_JikkenPy/app/backend/api/utils.py'> does not have the attribute 'load_trash_registry'\n\n======================================================================\nERROR: test_タグ配列バリデーション_0__ (api.tests.ProjectValidationTestCase.test_タグ配列バリデーション_0__)\n様々なタグ配列のバリデーション [with test_name='空のタグ配列', tags=[]]\n----------------------------------------------------------------------\nTraceback (most recent call last):\n  File \"/home/futaro/project/StatVizForge_JikkenPy/app/backend/api/test_base.py\", line 47, in setUp\n    self.mock_load_trash = load_trash_patcher.start()\n                           ^^^^^^^^^^^^^^^^^^^^^^^^^^\n  File \"/usr/lib/python3.12/unittest/mock.py\", line 1606, in start\n    result = self.__enter__()\n             ^^^^^^^^^^^^^^^^\n  File \"/usr/lib/python3.12/unittest/mock.py\", line 1458, in __enter__\n    original, local = self.get_original()\n                      ^^^^^^^^^^^^^^^^^^^\n  File \"/usr/lib/python3.12/unittest/mock.py\", line 1431, in get_original\n    raise AttributeError(\nAttributeError: <module 'api.utils' from '/home/futaro/project/StatVizForge_JikkenPy/app/backend/api/utils.py'> does not have the attribute 'load_trash_registry'\n\n======================================================================\nERROR: test_タグ配列バリデーション_1__ (api.tests.ProjectValidationTestCase.test_タグ配列バリデーション_1__)\n様々なタグ配列のバリデーション [with test_name='単一タグ', tags=['tag1']]\n----------------------------------------------------------------------\nTraceback (most recent call last):\n  File \"/home/futaro/project/StatVizForge_JikkenPy/app/backend/api/test_base.py\", line 47, in setUp\n    self.mock_load_trash = load_trash_patcher.start()\n                           ^^^^^^^^^^^^^^^^^^^^^^^^^^\n  File \"/usr/lib/python3.12/unittest/mock.py\", line 1606, in start\n    result = self.__enter__()\n             ^^^^^^^^^^^^^^^^\n  File \"/usr/lib/python3.12/unittest/mock.py\", line 1458, in __enter__\n    original, local = self.get_original()\n                      ^^^^^^^^^^^^^^^^^^^\n  File \"/usr/lib/python3.12/unittest/mock.py\", line 1431, in get_original\n    raise AttributeError(\nAttributeError: <module 'api.utils' from '/home/futaro/project/StatVizForge_JikkenPy/app/backend/api/utils.py'> does not have the attribute 'load_trash_registry'\n\n======================================================================\nERROR: test_タグ配列バリデーション_2__ (api.tests.ProjectValidationTestCase.test_タグ配列バリデーション_2__)\n様々なタグ配列のバリデーション [with test_name='複数タグ', tags=['tag1', 'tag2', 'tag3']]\n----------------------------------------------------------------------\nTraceback (most recent call last):\n  File \"/home/futaro/project/StatVizForge_JikkenPy/app/backend/api/test_base.py\", line 47, in setUp\n    self.mock_load_trash = load_trash_patcher.start()\n                           ^^^^^^^^^^^^^^^^^^^^^^^^^^\n  File \"/usr/lib/python3.12/unittest/mock.py\", line 1606, in start\n    result = self.__enter__()\n             ^^^^^^^^^^^^^^^^\n  File \"/usr/lib/python3.12/unittest/mock.py\", line 1458, in __enter__\n    original, local = self.get_original()\n                      ^^^^^^^^^^^^^^^^^^^\n  File \"/usr/lib/python3.12/unittest/mock.py\", line 1431, in get_original\n    raise AttributeError(\nAttributeError: <module 'api.utils' from '/home/futaro/project/StatVizForge_JikkenPy/app/backend/api/utils.py'> does not have the attribute 'load_trash_registry'\n\n======================================================================\nERROR: test_タグ配列バリデーション_3__ (api.tests.ProjectValidationTestCase.test_タグ配列バリデーション_3__)\n様々なタグ配列のバリデーション [with test_name='日本語タグ', tags=['日本語', 'テスト', 'サンプル']]\n----------------------------------------------------------------------\nTraceback (most recent call last):\n  File \"/home/futaro/project/StatVizForge_JikkenPy/app/backend/api/test_base.py\", line 47, in setUp\n    self.mock_load_trash = load_trash_patcher.start()\n                           ^^^^^^^^^^^^^^^^^^^^^^^^^^\n  File \"/usr/lib/python3.12/unittest/mock.py\", line 1606, in start\n    result = self.__enter__()\n             ^^^^^^^^^^^^^^^^\n  File \"/usr/lib/python3.12/unittest/mock.py\", line 1458, in __enter__\n    original, local = self.get_original()\n                      ^^^^^^^^^^^^^^^^^^^\n  File \"/usr/lib/python3.12/unittest/mock.py\", line 1431, in get_original\n    raise AttributeError(\nAttributeError: <module 'api.utils' from '/home/futaro/project/StatVizForge_JikkenPy/app/backend/api/utils.py'> does not have the attribute 'load_trash_registry'\n\n======================================================================\nERROR: test_タグ配列バリデーション_4__ (api.tests.ProjectValidationTestCase.test_タグ配列バリデーション_4__)\n様々なタグ配列のバリデーション [with test_name='英数字タグ', tags=['test', 'sample', 'demo123']]\n----------------------------------------------------------------------\nTraceback (most recent call last):\n  File \"/home/futaro/project/StatVizForge_JikkenPy/app/backend/api/test_base.py\", line 47, in setUp\n    self.mock_load_trash = load_trash_patcher.start()\n                           ^^^^^^^^^^^^^^^^^^^^^^^^^^\n  File \"/usr/lib/python3.12/unittest/mock.py\", line 1606, in start\n    result = self.__enter__()\n             ^^^^^^^^^^^^^^^^\n  File \"/usr/lib/python3.12/unittest/mock.py\", line 1458, in __enter__\n    original, local = self.get_original()\n                      ^^^^^^^^^^^^^^^^^^^\n  File \"/usr/lib/python3.12/unittest/mock.py\", line 1431, in get_original\n    raise AttributeError(\nAttributeError: <module 'api.utils' from '/home/futaro/project/StatVizForge_JikkenPy/app/backend/api/utils.py'> does not have the attribute 'load_trash_registry'\n\n======================================================================\nERROR: test_プロジェクト名バリデーション (api.tests.ProjectValidationTestCase.test_プロジェクト名バリデーション)\nプロジェクト名の長さと文字種バリデーション\n----------------------------------------------------------------------\nTraceback (most recent call last):\n  File \"/home/futaro/project/StatVizForge_JikkenPy/app/backend/api/test_base.py\", line 47, in setUp\n    self.mock_load_trash = load_trash_patcher.start()\n                           ^^^^^^^^^^^^^^^^^^^^^^^^^^\n  File \"/usr/lib/python3.12/unittest/mock.py\", line 1606, in start\n    result = self.__enter__()\n             ^^^^^^^^^^^^^^^^\n  File \"/usr/lib/python3.12/unittest/mock.py\", line 1458, in __enter__\n    original, local = self.get_original()\n                      ^^^^^^^^^^^^^^^^^^^\n  File \"/usr/lib/python3.12/unittest/mock.py\", line 1431, in get_original\n    raise AttributeError(\nAttributeError: <module 'api.utils' from '/home/futaro/project/StatVizForge_JikkenPy/app/backend/api/utils.py'> does not have the attribute 'load_trash_registry'\n\n======================================================================\nERROR: test_重複フォルダ名チェック (api.tests.ProjectValidationTestCase.test_重複フォルダ名チェック)\nフォルダ名の重複チェック\n----------------------------------------------------------------------\nTraceback (most recent call last):\n  File \"/home/futaro/project/StatVizForge_JikkenPy/app/backend/api/test_base.py\", line 47, in setUp\n    self.mock_load_trash = load_trash_patcher.start()\n                           ^^^^^^^^^^^^^^^^^^^^^^^^^^\n  File \"/usr/lib/python3.12/unittest/mock.py\", line 1606, in start\n    result = self.__enter__()\n             ^^^^^^^^^^^^^^^^\n  File \"/usr/lib/python3.12/unittest/mock.py\", line 1458, in __enter__\n    original, local = self.get_original()\n                      ^^^^^^^^^^^^^^^^^^^\n  File \"/usr/lib/python3.12/unittest/mock.py\", line 1431, in get_original\n    raise AttributeError(\nAttributeError: <module 'api.utils' from '/home/futaro/project/StatVizForge_JikkenPy/app/backend/api/utils.py'> does not have the attribute 'load_trash_registry'\n\n======================================================================\nFAIL: test_concurrent_tag_operations (api.test_file_tags.FileTagsAPITestCase.test_concurrent_tag_operations)\n並行タグ操作テスト\n----------------------------------------------------------------------\nTraceback (most recent call last):\n  File \"/home/futaro/project/StatVizForge_JikkenPy/app/backend/api/test_file_tags.py\", line 269, in test_concurrent_tag_operations\n    self.assertEqual(response.status_code, status.HTTP_200_OK)\nAssertionError: 404 != 200\n\n======================================================================\nFAIL: test_file_tags_persistence (api.test_file_tags.FileTagsAPITestCase.test_file_tags_persistence)\nファイルタグ永続化テスト\n----------------------------------------------------------------------\nTraceback (most recent call last):\n  File \"/home/futaro/project/StatVizForge_JikkenPy/app/backend/api/test_file_tags.py\", line 231, in test_file_tags_persistence\n    self.assertEqual(response.status_code, status.HTTP_200_OK)\nAssertionError: 404 != 200\n\n======================================================================\nFAIL: test_get_all_file_tags_success (api.test_file_tags.FileTagsAPITestCase.test_get_all_file_tags_success)\n全ファイルタグ取得成功テスト\n----------------------------------------------------------------------\nTraceback (most recent call last):\n  File \"/home/futaro/project/StatVizForge_JikkenPy/app/backend/api/test_file_tags.py\", line 127, in test_get_all_file_tags_success\n    self.assertEqual(response.status_code, status.HTTP_200_OK)\nAssertionError: 404 != 200\n\n======================================================================\nFAIL: test_get_file_tags_success (api.test_file_tags.FileTagsAPITestCase.test_get_file_tags_success)\nファイルタグ取得成功テスト\n----------------------------------------------------------------------\nTraceback (most recent call last):\n  File \"/home/futaro/project/StatVizForge_JikkenPy/app/backend/api/test_file_tags.py\", line 114, in test_get_file_tags_success\n    self.assertEqual(response.status_code, status.HTTP_200_OK)\nAssertionError: 404 != 200\n\n======================================================================\nFAIL: test_save_file_tags_invalid_combination (api.test_file_tags.FileTagsAPITestCase.test_save_file_tags_invalid_combination)\n無効なタグ組み合わせテスト（項目データのみ）\n----------------------------------------------------------------------\nTraceback (most recent call last):\n  File \"/home/futaro/project/StatVizForge_JikkenPy/app/backend/api/test_file_tags.py\", line 99, in test_save_file_tags_invalid_combination\n    self.assertEqual(response.status_code, status.HTTP_400_BAD_REQUEST)\nAssertionError: 404 != 400\n\n======================================================================\nFAIL: test_save_file_tags_success (api.test_file_tags.FileTagsAPITestCase.test_save_file_tags_success)\nファイルタグ保存成功テスト\n----------------------------------------------------------------------\nTraceback (most recent call last):\n  File \"/home/futaro/project/StatVizForge_JikkenPy/app/backend/api/test_file_tags.py\", line 68, in test_save_file_tags_success\n    self.assertEqual(response.status_code, status.HTTP_200_OK)\nAssertionError: 404 != 200\n\n======================================================================\nFAIL: test_save_file_tags_validation_error (api.test_file_tags.FileTagsAPITestCase.test_save_file_tags_validation_error)\nファイルタグ保存バリデーションエラーテスト\n----------------------------------------------------------------------\nTraceback (most recent call last):\n  File \"/home/futaro/project/StatVizForge_JikkenPy/app/backend/api/test_file_tags.py\", line 83, in test_save_file_tags_validation_error\n    self.assertEqual(response.status_code, status.HTTP_400_BAD_REQUEST)\nAssertionError: 404 != 400\n\n======================================================================\nFAIL: test_tag_api_error_handling (api.test_file_tags.FileTagsAPITestCase.test_tag_api_error_handling)\nタグAPIエラーハンドリングテスト\n----------------------------------------------------------------------\nTraceback (most recent call last):\n  File \"/home/futaro/project/StatVizForge_JikkenPy/app/backend/api/test_file_tags.py\", line 285, in test_tag_api_error_handling\n    self.assertEqual(response.status_code, status.HTTP_500_INTERNAL_SERVER_ERROR)\nAssertionError: 404 != 500\n\n======================================================================\nFAIL: test_tag_api_response_format (api.test_file_tags.FileTagsAPITestCase.test_tag_api_response_format)\nタグAPIレスポンス形式テスト\n----------------------------------------------------------------------\nTraceback (most recent call last):\n  File \"/home/futaro/project/StatVizForge_JikkenPy/app/backend/api/test_file_tags.py\", line 306, in test_tag_api_response_format\n    self.assertEqual(response.status_code, status.HTTP_200_OK)\nAssertionError: 404 != 200\n\n======================================================================\nFAIL: test_tag_validation_rules (api.test_file_tags.FileTagsAPITestCase.test_tag_validation_rules)\nタグバリデーションルールテスト\n----------------------------------------------------------------------\nTraceback (most recent call last):\n  File \"/home/futaro/project/StatVizForge_JikkenPy/app/backend/api/test_file_tags.py\", line 200, in test_tag_validation_rules\n    self.assertEqual(response.status_code, status.HTTP_200_OK)\nAssertionError: 404 != 200\n\n======================================================================\nFAIL: test_jupyter_api_resource_management (api.test_jupyter_api.JupyterLabAPITestCase.test_jupyter_api_resource_management)\nJupyterLab API リソース管理テスト\n----------------------------------------------------------------------\nTraceback (most recent call last):\n  File \"/home/futaro/project/StatVizForge_JikkenPy/app/backend/api/test_jupyter_api.py\", line 244, in test_jupyter_api_resource_management\n    self.assertEqual(response.status_code, status.HTTP_200_OK)\nAssertionError: 404 != 200\n\n======================================================================\nFAIL: test_jupyter_api_security (api.test_jupyter_api.JupyterLabAPITestCase.test_jupyter_api_security)\nJupyterLab API セキュリティテスト\n----------------------------------------------------------------------\nTraceback (most recent call last):\n  File \"/home/futaro/project/StatVizForge_JikkenPy/app/backend/api/test_jupyter_api.py\", line 220, in test_jupyter_api_security\n    self.assertEqual(response.status_code, status.HTTP_200_OK)\nAssertionError: 404 != 200\n\n======================================================================\nFAIL: test_start_jupyter_lab_already_running (api.test_jupyter_api.JupyterLabAPITestCase.test_start_jupyter_lab_already_running)\n既に起動中のJupyterLabに対する処理テスト\n----------------------------------------------------------------------\nTraceback (most recent call last):\n  File \"/usr/lib/python3.12/unittest/mock.py\", line 1390, in patched\n    return func(*newargs, **newkeywargs)\n           ^^^^^^^^^^^^^^^^^^^^^^^^^^^^^\n  File \"/home/futaro/project/StatVizForge_JikkenPy/app/backend/api/test_jupyter_api.py\", line 101, in test_start_jupyter_lab_already_running\n    self.assertEqual(response.status_code, status.HTTP_200_OK)\nAssertionError: 404 != 200\n\n======================================================================\nFAIL: test_start_jupyter_lab_startup_failure (api.test_jupyter_api.JupyterLabAPITestCase.test_start_jupyter_lab_startup_failure)\nJupyterLab起動失敗テスト\n----------------------------------------------------------------------\nTraceback (most recent call last):\n  File \"/usr/lib/python3.12/unittest/mock.py\", line 1390, in patched\n    return func(*newargs, **newkeywargs)\n           ^^^^^^^^^^^^^^^^^^^^^^^^^^^^^\n  File \"/home/futaro/project/StatVizForge_JikkenPy/app/backend/api/test_jupyter_api.py\", line 188, in test_start_jupyter_lab_startup_failure\n    self.assertEqual(response.status_code, status.HTTP_500_INTERNAL_SERVER_ERROR)\nAssertionError: 404 != 500\n\n======================================================================\nFAIL: test_start_jupyter_lab_success (api.test_jupyter_api.JupyterLabAPITestCase.test_start_jupyter_lab_success)\nJupyterLab起動成功テスト\n----------------------------------------------------------------------\nTraceback (most recent call last):\n  File \"/usr/lib/python3.12/unittest/mock.py\", line 1390, in patched\n    return func(*newargs, **newkeywargs)\n           ^^^^^^^^^^^^^^^^^^^^^^^^^^^^^\n  File \"/home/futaro/project/StatVizForge_JikkenPy/app/backend/api/test_jupyter_api.py\", line 56, in test_start_jupyter_lab_success\n    self.assertEqual(response.status_code, status.HTTP_200_OK)\nAssertionError: 404 != 200\n\n======================================================================\nFAIL: test_add_file_comment (api.tests.FileCommentsTestCase.test_add_file_comment)\nファイルコメント追加テスト\n----------------------------------------------------------------------\nTraceback (most recent call last):\n  File \"/usr/lib/python3.12/unittest/mock.py\", line 1390, in patched\n    return func(*newargs, **newkeywargs)\n           ^^^^^^^^^^^^^^^^^^^^^^^^^^^^^\n  File \"/home/futaro/project/StatVizForge_JikkenPy/app/backend/api/tests.py\", line 797, in test_add_file_comment\n    self.assertEqual(response.status_code, status.HTTP_201_CREATED)\nAssertionError: 404 != 201\n\n======================================================================\nFAIL: test_comment_api_validation (api.tests.FileCommentsTestCase.test_comment_api_validation)\nコメントAPI バリデーションテスト\n----------------------------------------------------------------------\nTraceback (most recent call last):\n  File \"/home/futaro/project/StatVizForge_JikkenPy/app/backend/api/tests.py\", line 856, in test_comment_api_validation\n    self.assertEqual(response.status_code, status.HTTP_400_BAD_REQUEST)\nAssertionError: 404 != 400\n\n======================================================================\nFAIL: test_delete_file_comment (api.tests.FileCommentsTestCase.test_delete_file_comment)\nファイルコメント削除テスト\n----------------------------------------------------------------------\nTraceback (most recent call last):\n  File \"/usr/lib/python3.12/unittest/mock.py\", line 1390, in patched\n    return func(*newargs, **newkeywargs)\n           ^^^^^^^^^^^^^^^^^^^^^^^^^^^^^\n  File \"/home/futaro/project/StatVizForge_JikkenPy/app/backend/api/tests.py\", line 842, in test_delete_file_comment\n    self.assertEqual(response.status_code, status.HTTP_200_OK)\nAssertionError: 404 != 200\n\n======================================================================\nFAIL: test_get_file_comments (api.tests.FileCommentsTestCase.test_get_file_comments)\nファイルコメント取得テスト\n----------------------------------------------------------------------\nTraceback (most recent call last):\n  File \"/usr/lib/python3.12/unittest/mock.py\", line 1390, in patched\n    return func(*newargs, **newkeywargs)\n           ^^^^^^^^^^^^^^^^^^^^^^^^^^^^^\n  File \"/home/futaro/project/StatVizForge_JikkenPy/app/backend/api/tests.py\", line 766, in test_get_file_comments\n    self.assertEqual(response.status_code, status.HTTP_200_OK)\nAssertionError: 404 != 200\n\n======================================================================\nFAIL: test_update_file_comment (api.tests.FileCommentsTestCase.test_update_file_comment)\nファイルコメント更新テスト\n----------------------------------------------------------------------\nTraceback (most recent call last):\n  File \"/usr/lib/python3.12/unittest/mock.py\", line 1390, in patched\n    return func(*newargs, **newkeywargs)\n           ^^^^^^^^^^^^^^^^^^^^^^^^^^^^^\n  File \"/home/futaro/project/StatVizForge_JikkenPy/app/backend/api/tests.py\", line 826, in test_update_file_comment\n    self.assertEqual(response.status_code, status.HTTP_200_OK)\nAssertionError: 404 != 200\n\n======================================================================\nFAIL: test_directory_creation (api.tests.FileManagementTestCase.test_directory_creation)\nディレクトリ作成テスト\n----------------------------------------------------------------------\nTraceback (most recent call last):\n  File \"/usr/lib/python3.12/unittest/mock.py\", line 1390, in patched\n    return func(*newargs, **newkeywargs)\n           ^^^^^^^^^^^^^^^^^^^^^^^^^^^^^\n  File \"/home/futaro/project/StatVizForge_JikkenPy/app/backend/api/tests.py\", line 707, in test_directory_creation\n    self.assertEqual(response.status_code, status.HTTP_200_OK)\nAssertionError: 404 != 200\n\n======================================================================\nFAIL: test_directory_tree_retrieval (api.tests.FileManagementTestCase.test_directory_tree_retrieval)\nディレクトリツリー取得テスト\n----------------------------------------------------------------------\nTraceback (most recent call last):\n  File \"/usr/lib/python3.12/unittest/mock.py\", line 1390, in patched\n    return func(*newargs, **newkeywargs)\n           ^^^^^^^^^^^^^^^^^^^^^^^^^^^^^\n  File \"/home/futaro/project/StatVizForge_JikkenPy/app/backend/api/tests.py\", line 501, in test_directory_tree_retrieval\n    self.assertEqual(response.status_code, status.HTTP_200_OK)\nAssertionError: 404 != 200\n\n======================================================================\nFAIL: test_file_api_error_handling (api.tests.FileManagementTestCase.test_file_api_error_handling)\nファイルAPI エラーハンドリングテスト\n----------------------------------------------------------------------\nTraceback (most recent call last):\n  File \"/home/futaro/project/StatVizForge_JikkenPy/app/backend/api/tests.py\", line 725, in test_file_api_error_handling\n    self.assertEqual(response.status_code, status.HTTP_400_BAD_REQUEST)\nAssertionError: 404 != 400\n\n======================================================================\nFAIL: test_file_deletion (api.tests.FileManagementTestCase.test_file_deletion)\nファイル削除テスト\n----------------------------------------------------------------------\nTraceback (most recent call last):\n  File \"/usr/lib/python3.12/unittest/mock.py\", line 1390, in patched\n    return func(*newargs, **newkeywargs)\n           ^^^^^^^^^^^^^^^^^^^^^^^^^^^^^\n  File \"/home/futaro/project/StatVizForge_JikkenPy/app/backend/api/tests.py\", line 660, in test_file_deletion\n    self.assertEqual(response.status_code, status.HTTP_200_OK)\nAssertionError: 404 != 200\n\n======================================================================\nFAIL: test_file_move (api.tests.FileManagementTestCase.test_file_move)\nファイル移動テスト\n----------------------------------------------------------------------\nTraceback (most recent call last):\n  File \"/usr/lib/python3.12/unittest/mock.py\", line 1390, in patched\n    return func(*newargs, **newkeywargs)\n           ^^^^^^^^^^^^^^^^^^^^^^^^^^^^^\n  File \"/home/futaro/project/StatVizForge_JikkenPy/app/backend/api/tests.py\", line 683, in test_file_move\n    self.assertEqual(response.status_code, status.HTTP_200_OK)\nAssertionError: 404 != 200\n\n======================================================================\nFAIL: test_file_search (api.tests.FileManagementTestCase.test_file_search)\nファイル検索テスト\n----------------------------------------------------------------------\nTraceback (most recent call last):\n  File \"/usr/lib/python3.12/unittest/mock.py\", line 1390, in patched\n    return func(*newargs, **newkeywargs)\n           ^^^^^^^^^^^^^^^^^^^^^^^^^^^^^\n  File \"/home/futaro/project/StatVizForge_JikkenPy/app/backend/api/tests.py\", line 634, in test_file_search\n    self.assertEqual(response.status_code, status.HTTP_200_OK)\nAssertionError: 404 != 200\n\n======================================================================\nFAIL: test_multiple_file_upload (api.tests.FileManagementTestCase.test_multiple_file_upload)\n複数ファイルアップロードテスト\n----------------------------------------------------------------------\nTraceback (most recent call last):\n  File \"/usr/lib/python3.12/unittest/mock.py\", line 1390, in patched\n    return func(*newargs, **newkeywargs)\n           ^^^^^^^^^^^^^^^^^^^^^^^^^^^^^\n  File \"/home/futaro/project/StatVizForge_JikkenPy/app/backend/api/tests.py\", line 586, in test_multiple_file_upload\n    self.assertEqual(response.status_code, status.HTTP_201_CREATED)\nAssertionError: 404 != 201\n\n======================================================================\nFAIL: test_single_file_upload (api.tests.FileManagementTestCase.test_single_file_upload)\n単一ファイルアップロードテスト\n----------------------------------------------------------------------\nTraceback (most recent call last):\n  File \"/usr/lib/python3.12/unittest/mock.py\", line 1390, in patched\n    return func(*newargs, **newkeywargs)\n           ^^^^^^^^^^^^^^^^^^^^^^^^^^^^^\n  File \"/home/futaro/project/StatVizForge_JikkenPy/app/backend/api/tests.py\", line 540, in test_single_file_upload\n    self.assertEqual(response.status_code, status.HTTP_201_CREATED)\nAssertionError: 404 != 201\n\n----------------------------------------------------------------------\nRan 56 tests in 0.062s\n\nFAILED (failures=28, errors=36)\nDestroying test database for alias 'default' ('file:memorydb_default?mode=memory&cache=shared')...\n",
      "rawOutput": "Found 56 test(s).\nOperations to perform:\n  Synchronize unmigrated apps: corsheaders, messages, rest_framework, staticfiles\n  Apply all migrations: admin, api, auth, contenttypes, sessions\nSynchronizing apps without migrations:\n  Creating tables...\n    Running deferred SQL...\nRunning migrations:\n  Applying contenttypes.0001_initial... OK\n  Applying auth.0001_initial... OK\n  Applying admin.0001_initial... OK\n  Applying admin.0002_logentry_remove_auto_add... OK\n  Applying admin.0003_logentry_add_action_flag_choices... OK\n  Applying api.0001_initial... OK\n  Applying contenttypes.0002_remove_content_type_name... OK\n  Applying auth.0002_alter_permission_name_max_length... OK\n  Applying auth.0003_alter_user_email_max_length... OK\n  Applying auth.0004_alter_user_username_opts... OK\n  Applying auth.0005_alter_user_last_login_null... OK\n  Applying auth.0006_require_contenttypes_0002... OK\n  Applying auth.0007_alter_validators_add_error_messages... OK\n  Applying auth.0008_alter_user_username_max_length... OK\n  Applying auth.0009_alter_user_last_name_max_length... OK\n  Applying auth.0010_alter_group_name_max_length... OK\n  Applying auth.0011_update_proxy_permissions... OK\n  Applying auth.0012_alter_user_first_name_max_length... OK\n  Applying sessions.0001_initial... OK\nSystem check identified no issues (0 silenced).\n✅ プロジェクトバックアップ作成完了: /tmp/django_test_backup_rw9xycn4\n✅ プロジェクトフォルダ復元完了\n🧹 バックアップファイル削除完了\n✅ プロジェクトバックアップ作成完了: /tmp/django_test_backup_vp61s0d7\n✅ プロジェクトフォルダ復元完了\n🧹 バックアップファイル削除完了\n\n=== ファイルコメント追加テスト開始 ===\n\n=== コメントAPI バリデーションテスト開始 ===\n\n=== ファイルコメント削除テスト開始 ===\n\n=== ファイルコメント取得テスト開始 ===\n\n=== ファイルコメント更新テスト開始 ===\n\n=== ディレクトリ作成テスト開始 ===\n\n=== ディレクトリツリー取得テスト開始 ===\n\n=== ファイルAPI エラーハンドリングテスト開始 ===\n✓ 存在しないプロジェクトフォルダエラー確認\n\n=== ファイル削除テスト開始 ===\n\n=== ファイル移動テスト開始 ===\n\n=== ファイル検索テスト開始 ===\n\n=== 複数ファイルアップロードテスト開始 ===\n\n=== 単一ファイルアップロードテスト開始 ===\n\n=== パフォーマンステスト開始 ===\n✓ プロジェクト一覧取得応答時間: 0.001秒\n=== パフォーマンステスト完了 ===\n"
    }
  }
}